Workbook

Sheet README
A1: Recipes for POS - normalized workbook
A2: Purpose | B2: Transpose the original wide recipe-costing sheet into app-friendly tabs.
A3: Source workbook | B3: https://docs.google.com/spreadsheets/d/1MDDgsjl6ZxmfJe2bMK8kLi3vLb7xyTPY88UAPB9R6-c/edit?usp=sharing
A4: Source shape | B4: One recipe row followed by repeated component blocks across Component 1-11.
A5: Created from | B5: 138 recipes and 514 component rows transposed from the visible source data.
A6: Tabs | B6: Recipes, Recipe_Components, Menus, Menu_Lines, Venue_Summary
A7: Notes | B7: calc_component_cost, variance_calc and gp_calc are formula-driven. Demo menus are included for app wiring and can be replaced.

Sheet Validation
A1: Recipes for POS normalization QA
A3: Source workbook row range reviewed | B3: 1 to 157
A4: Normalized recipe rows | B4: 138
A5: Normalized component rows | B5: 514
A6: Orphan components | B6: 0
A7: Duplicate source_row values | B7: 0
A8: Blank separator rows skipped | B8: 19
A9: Recipes with missing or zero sale price | B9: 44
A10: Source vs component-cost mismatches | B10: 6
A12: Interpretation
A13: • The 19 skipped source rows are separator / blank rows between menu sections, not missing recipes.
A14: • The normalized workbook carries 138 recipe rows and 514 component rows.
A15: • Six recipes show a mismatch between the source row-level COST and the sum of imported components. These were preserved and flagged below rather than overwritten silently.
A16: • Rows with blank or zero selling price were preserved from source so pricing gaps can be fixed later without losing recipes.
A18: separator_source_rows_intentionally_skipped
A19: 7
A20: 19
A21: 31
A22: 32
A23: 33
A24: 38
A25: 44
A26: 51
A27: 69
A28: 76
A29: 83
A30: 88
... A37: 146
A39: recipe_id | B39: source_row | C39: restaurant | D39: name | E39: source_cost | F39: component_cost_sum | G39: delta
A40: 20 | B40: 22 | C40: Tasi | D40: Fried Halloumi with Warmed Honey & Thyme | E40: 0 | F40: 0.6375 | G40: 0.6375
A41: 43 | B41: 50 | C41: Tasi | D41: Broccoli | E41: 0 | F41: 1.068 | G41: 1.068
A42: 124 | B42: 142 | C42: Mikro Nisi | D42: Greek salad with crumbled manouri cheese | E42: 2.448 | F42: 2.4529 | G42: 0.0049
A43: 133 | B43: 152 | C43: Mikro Nisi | D43: Chicken Stifado | E43: 2.1639 | F43: 2.201 | G43: 0.0371
A44: 135 | B44: 154 | C44: Mikro Nisi | D44: Baked Seabass, wild rice and spinach | E44: 6.61012 | F44: 6.64012 | G44: 0.03
A45: 138 | B45: 157 | C45: Mikro Nisi | D45: Pork Gyros Special | E45: 2.0361671 | F45: 2.0316671 | G45: -0.0045000001

Sheet Recipe_Components
A1: recipe_id | B1: component_sort | C1: ingredient_name | D1: ingredient_item_code | E1: quantity_by_weight_grams | F1: component_cost
A2: 1 | B2: 1 | C2: Beef fillet | D2: 101.BEEF4 | E2: 80 | F2: 2.384
A3: 1 | B3: 2 | C3: Rocket | D3: 106.FRVEG156 | E3: 50 | F3: 0.375
A4: 1 | B4: 3 | C4: Parmesan | D4: 106.CHE43 | E4: 20 | F4: 0.276
A5: 1 | B5: 4 | C5: olive oil | D5: 109.OIL1 | E5: 10 | F5: 0.06
A6: 1 | B6: 5 | C6: Onion | E6: 10
A7: 2 | B7: 1 | C7: Courgette | D7: 106.FRVEG19 | E7: 170 | F7: 0.425
A8: 2 | B8: 2 | C8: flour | D8: 107.FLO1 | E8: 40 | F8: 0.0344
A9: 2 | B9: 3 | C9: garlic powder | D9: 107.SPIC15 | E9: 3 | F9: 0.03654
A10: 2 | B10: 4 | C10: garlic | D10: 106.FRVEG10 | E10: 5 | F10: 0.037
A11: 2 | B11: 5 | C11: Fresh parsley | D11: 106.FRVEG42 | E11: 5 | F11: 0.0045
A12: 2 | B12: 6 | C12: Baking Powder | D12: 107.FLO3 | E12: 2 | F12: 0.0098
A13: 2 | B13: 7 | C13: Spicy Tomato Sauce Batch | D13: BCH004 | E13: 50 | F13: 0.1351
A14: 3 | B14: 1 | C14: Sea bass fillet | D14: BCH011 | E14: 60 | F14: 1.95
A15: 3 | B15: 2 | C15: lime juice | D15: 106.FRVEG37 | E15: 30 | F15: 0.45
A16: 3 | B16: 3 | C16: Red Onion | D16: 106.FRVEG18 | E16: 75 | F16: 0.09375
A17: 3 | B17: 4 | C17: green chilli | D17: 106.FRVEG103 | E17: 10 | F17: 0.125
A18: 3 | B18: 5 | C18: coriander | D18: 106.FRVEG11 | E18: 50 | F18: 0.1
... A100: 25 | B100: 3 | C100: Rocket | D100: 106.FRVEG156 | E100: 40 | F100: 0.3
A101: 25 | B101: 4 | C101: Parmesan
A102: 29 | B102: 1 | C102: Gem lettuce | D102: 106.FRVEG36 | E102: 100 | F102: 0.42
A103: 29 | B103: 2 | C103: bacon | D103: 106.COCU13 | E103: 30 | F103: 0.2325
A104: 29 | B104: 3 | C104: croutons | D104: 107.BRE38 | E104: 20 | F104: 0
A105: 29 | B105: 4 | C105: chicken breast | D105: 101.CHI9 | E105: 100 | F105: 0.68
A106: 29 | B106: 5 | C106: Caesar Dressing Batch | D106: BCH001 | E106: 50 | F106: 0.31214
A107: 29 | B107: 6 | C107: Parmesan | D107: 106.CHE43 | E107: 5 | F107: 0.069
A108: 30 | B108: 1 | C108: Tomato | D108: 106.FRVEG13 | E108: 250 | F108: 0.65
A109: 30 | B109: 2 | C109: cucumber | D109: 106.FRVEG84 | E109: 50 | F109: 0.035
A110: 30 | B110: 3 | C110: green peppers | D110: 106.FRVEG61 | E110: 20 | F110: 0.046
A111: 30 | B111: 4 | C111: Red Onion | D111: 106.FRVEG18 | E111: 10 | F111: 0.0125
A112: 30 | B112: 5 | C112: feta | D112: 106.CHE14 | E112: 60 | F112: 0.6042
A113: 30 | B113: 6 | C113: olive oil | D113: 109.OIL1 | E113: 30 | F113: 0.18
... A165: 37 | B165: 3 | C165: Mozzarella | D165: 106.CHE39 | E165: 100 | F165: 2.535
A166: 37 | B166: 4 | C166: Salami | D166: ING048 | E166: 30
A167: 38 | B167: 1 | C167: frozen fries | D167: 103.VEG4 | E167: 200 | F167: 0.456
A168: 39 | B168: 1 | C168: Frozen fries | D168: 103.VEG4 | E168: 200 | F168: 0.456
A169: 39 | B169: 2 | C169: Parmesan | D169: 106.CHE43 | E169: 30 | F169: 0.414
A170: 40 | B170: 1 | C170: New Potatoes | D170: ING013 | E170: 200 | F170: 0
A171: 40 | B171: 2 | C171: Butter | D171: 106.BUT10 | E171: 10 | F171: 0.106
A172: 40 | B172: 3 | C172: Basil | D172: 106.FRVEG5 | E172: 2 | F172: 0.004
...

Sheet Recipes
A1: recipe_id | B1: source_row | C1: restaurant | D1: name | E1: category | F1: selling_item_code | G1: current_sale_price | H1: roundup | I1: net_price_source | J1: gross_price_source | K1: source_cost | L1: calc_component_cost | M1: cost_delta_vs_source | N1: variance_calc | O1: gp_calc | P1: pos_ytd | Q1: recipe_complete | R1: pricing_complete | S1: source_variance_raw | T1: source_gp_raw
A2: 1 | B2: 1 | C2: Tasi | D2: Beef carpaccio | E2: TASTART | F2: TASTART01 | G2: 14 | H2: 14.3 | I2: 10.316667 | J2: 12.792667 | K2: 3.095 | L2: =SUMIF(Recipe_Components!$A$2:$A$515,A2,Recipe_Components!$F$2:$F$515) | M2: =IF(AND(K2<>"",L2<>""),L2-K2,"") | N2: =IF(AND(G2<>"",H2<>""),G2-H2,"") | O2: =IF(G2>0,1-L2/G2,"") | Q2: FALSE | R2: FALSE | S2: -0.3 | T2: 0.7258714286
A3: 2 | B3: 2 | C3: Tasi | D3: Courgette fritters | E3: TASTART | F3: TASTART02 | G3: 10 | H3: 3.3 | I3: 2.2744667 | J3: 2.8203387 | K3: 0.68234 | L3: =SUMIF(Recipe_Components!$A$2:$A$515,A3,Recipe_Components!$F$2:$F$515) | M3: =IF(AND(K3<>"",L3<>""),L3-K3,"") | N3: =IF(AND(G3<>"",H3<>""),G3-H3,"") | O3: =IF(G3>0,1-L3/G3,"") | Q3: FALSE | R3: FALSE | S3: 6.7 | T3: 0.91538984
A4: 3 | B4: 3 | C4: Tasi | D4: Seabass ceviche | E4: TASTART | F4: TASTART03 | G4: 14 | H4: 15.4 | I4: 10.814167 | J4: 13.409567 | K4: 3.24425 | L4: =SUMIF(Recipe_Components!$A$2:$A$515,A4,Recipe_Components!$F$2:$F$515) | M4: =IF(AND(K4<>"",L4<>""),L4-K4,"") | N4: =IF(AND(G4<>"",H4<>""),G4-H4,"") | O4: =IF(G4>0,1-L4/G4,"") | Q4: FALSE | R4: FALSE | S4: -1.4 | T4: 0.7126521429
A5: 4 | B5: 4 | C5: Tasi | D5: Gazpacho | E5: TASTART | F5: TASTART04 | G5: 10 | H5: 4.4 | I5: 2.7830769 | J5: 3.4510154 | K5: 0.83492308 | L5: =SUMIF(Recipe_Components!$A$2:$A$515,A5,Recipe_Components!$F$2:$F$515) | M5: =IF(AND(K5<>"",L5<>""),L5-K5,"") | N5: =IF(AND(G5<>"",H5<>""),G5-H5,"") | O5: =IF(G5>0,1-L5/G5,"") | Q5: FALSE | R5: FALSE | S5: 5.6 | T5: 0.8964695385
A6: 5 | B6: 5 | C6: Tasi | D6: Fritto misto | E6: TASTART | F6: TASTART05 | G6: 16 | H6: 17.6 | I6: 12.860648 | J6: 15.947204 | K6: 3.8581944 | L6: =SUMIF(Recipe_Components!$A$2:$A$515,A6,Recipe_Components!$F$2:$F$515) | M6: =IF(AND(K6<>"",L6<>""),L6-K6,"") | N6: =IF(AND(G6<>"",H6<>""),G6-H6,"") | O6: =IF(G6>0,1-L6/G6,"") | Q6: FALSE | R6: FALSE | S6: -1.6 | T6: 0.7009899306
A7: 6 | B7: 6 | C7: Tasi | D7: White bean dip and flatbread | E7: TASTART | F7: TASTART06 | G7: 10 | H7: 4.4 | I7: 2.6811696 | J7: 3.3246504 | K7: 0.80435089 | L7: =SUMIF(Recipe_Components!$A$2:$A$515,A7,Recipe_Components!$F$2:$F$515) | M7: =IF(AND(K7<>"",L7<>""),L7-K7,"") | N7: =IF(AND(G7<>"",H7<>""),G7-H7,"") | O7: =IF(G7>0,1-L7/G7,"") | Q7: FALSE | R7: FALSE | S7: 5.6 | T7: 0.9002604891
A8: 7 | B8: 8 | C8: Tasi | D8: Spinach and sea green linguine | E8: TAMAIN | F8: TAMAIN01 | G8: 16 | H8: 17.6 | I8: 12.161333 | J8: 15.080053 | K8: 3.6484 | L8: =SUMIF(Recipe_Components!$A$2:$A$515,A8,Recipe_Components!$F$2:$F$515) | M8: =IF(AND(K8<>"",L8<>""),L8-K8,"") | N8: =IF(AND(G8<>"",H8<>""),G8-H8,"") | O8: =IF(G8>0,1-L8/G8,"") | Q8: FALSE | R8: FALSE | S8: -1.6 | T8: 0.717249
A9: 8 | B9: 9 | C9: Tasi | D9: GF Spinach and sea green linguine | E9: TAMAIN | F9: TAMAIN02 | G9: 16 | H9: 17.6 | I9: 12.161333 | J9: 15.080053 | K9: 3.6484 | L9: =SUMIF(Recipe_Components!$A$2:$A$515,A9,Recipe_Components!$F$2:$F$515) | M9: =IF(AND(K9<>"",L9<>""),L9-K9,"") | N9: =IF(AND(G9<>"",H9<>""),G9-H9,"") | O9: =IF(G9>0,1-L9/G9,"") | Q9: FALSE | R9: FALSE | S9: -1.6 | T9: 0.717249
A10: 9 | B10: 10 | C10: Tasi | D10: Beef Ragu Orecchiette | E10: TAMAIN | F10: TAMAIN03 | G10: 18 | H10: 17.6 | I10: 12.274012 | J10: 15.219775 | K10: 3.6822037 | L10: =SUMIF(Recipe_Components!$A$2:$A$515,A10,Recipe_Components!$F$2:$F$515) | M10: =IF(AND(K10<>"",L10<>""),L10-K10,"") | N10: =IF(AND(G10<>"",H10<>""),G10-H10,"") | O10: =IF(G10>0,1-L10/G10,"") | Q10: FALSE | R10: FALSE | S10: 0.4 | T10: 0.7463370773
A11: 10 | B11: 11 | C11: Tasi | D11: GF Beef Rugu Orecchiette | E11: TAMAIN | F11: TAMAIN04 | G11: 18 | H11: 18.7 | I11: 13.055346 | J11: 16.188629 | K11: 3.9166037 | L11: =SUMIF(Recipe_Components!$A$2:$A$515,A11,Recipe_Components!$F$2:$F$515) | M11: =IF(AND(K11<>"",L11<>""),L11-K11,"") | N11: =IF(AND(G11<>"",H11<>""),G11-H11,"") | O11: =IF(G11>0,1-L11/G11,"") | Q11: FALSE | R11: FALSE | S11: -0.7 | T11: 0.7301895217
A12: 11 | B12: 12 | C12: Tasi | D12: Seafood linguine | E12: TAMAIN | F12: TAMAIN05 | G12: 28 | H12: 11 | I12: 8.0165333 | J12: 9.9405013 | K12: 2.40496 | L12: =SUMIF(Recipe_Components!$A$2:$A$515,A12,Recipe_Components!$F$2:$F$515) | M12: =IF(AND(K12<>"",L12<>""),L12-K12,"") | N12: =IF(AND(G12<>"",H12<>""),G12-H12,"") | O12: =IF(G12>0,1-L12/G12,"") | Q12: FALSE | R12: FALSE | S12: 17 | T12: 0.8934946286
A13: 12 | B13: 13 | C13: Tasi | D13: GF seafood linguine | E13: TAMAIN | F13: TAMAIN06 | G13: 28 | H13: 11 | I13: 8.0165333 | J13: 9.9405013 | K13: 2.40496 | L13: =SUMIF(Recipe_Components!$A$2:$A$515,A13,Recipe_Components!$F$2:$F$515) | M13: =IF(AND(K13<>"",L13<>""),L13-K13,"") | N13: =IF(AND(G13<>"",H13<>""),G13-H13,"") | O13: =IF(G13>0,1-L13/G13,"") | Q13: FALSE | R13: FALSE | S13: 17 | T13: 0.8934946286
... A17: 16 | B17: 17 | C17: Tasi | D17: Pomodoro Lingiuini | E17: TAMAIN | F17: TAMAIN10 | G17: 16 | H17: 6.6 | I17: 4.1793588 | J17: 5.1824049 | K17: 1.2538076 | L17: =SUMIF(Recipe_Components!$A$2:$A$515,A17,Recipe_Components!$F$2:$F$515) | M17: =IF(AND(K17<>"",L17<>""),L17-K17,"") | N17: =IF(AND(G17<>"",H17<>""),G17-H17,"") | O17: =IF(G17>0,1-L17/G17,"") | Q17: TRUE | R17: FALSE | S17: 9.4 | T17: 0.902829909
A18: 17 | B18: 18 | C18: Tasi | D18: Marinated Grilled Aubergine | E18: TAMAIN | F18: TAMAIN11 | G18: 19 | H18: 5.5 | I18: 3.8373333 | J18: 4.7582933 | K18: 1.1512 | L18: =SUMIF(Recipe_Components!$A$2:$A$515,A18,Recipe_Components!$F$2:$F$515) | M18: =IF(AND(K18<>"",L18<>""),L18-K18,"") | N18: =IF(AND(G18<>"",H18<>""),G18-H18,"") | O18: =IF(G18>0,1-L18/G18,"") | Q18: FALSE | R18: FALSE | T18: 0.9248690526
A19: 18 | B19: 20 | C19: Tasi | D19: Grilled Leg Lamb (special Sept) | E19: TASPEC | F19: TASPEC01 | G19: 26 | H19: 24.2 | I19: 17.115667 | J19: 21.223427 | K19: 5.1347 | L19: =SUMIF(Recipe_Components!$A$2:$A$515,A19,Recipe_Components!$F$2:$F$515) | M19: =IF(AND(K19<>"",L19<>""),L19-K19,"") | N19: =IF(AND(G19<>"",H19<>""),G19-H19,"") | O19: =IF(G19>0,1-L19/G19,"") | Q19: FALSE | R19: FALSE | T19: 0.7551143077
A20: 19 | B20: 21 | C20: Tasi | D20: Fregola sarda con le cozze | E20: TASPEC | F20: TASPEC02 | G20: 0 | L20: =SUMIF(Recipe_Components!$A$2:$A$515,A20,Recipe_Components!$F$2:$F$515) | M20: =IF(AND(K20<>"",L20<>""),L20-K20,"") | N20: =IF(AND(G20<>"",H20<>""),G20-H20,"") | O20: =IF(G20>0,1-L20/G20,"") | Q20: FALSE | R20: FALSE
A21: 20 | B21: 22 | C21: Tasi | D21: Fried Halloumi with Warmed Honey & Thyme | E21: TASPEC | F21: TASPEC03 | G21: 0 | L21: =SUMIF(Recipe_Components!$A$2:$A$515,A21,Recipe_Components!$F$2:$F$515) | M21: =IF(AND(K21<>"",L21<>""),L21-K21,"") | N21: =IF(AND(G21<>"",H21<>""),G21-H21,"") | O21: =IF(G21>0,1-L21/G21,"") | Q21: FALSE | R21: FALSE
A22: 21 | B22: 23 | C22: Tasi | D22: Prawn, Clam & Squid Linguini | E22: TASPEC | F22: TASPEC04 | G22: 0 | L22: =SUMIF(Recipe_Components!$A$2:$A$515,A22,Recipe_Components!$F$2:$F$515) | M22: =IF(AND(K22<>"",L22<>""),L22-K22,"") | N22: =IF(AND(G22<>"",H22<>""),G22-H22,"") | O22: =IF(G22>0,1-L22/G22,"") | Q22: FALSE | R22: FALSE
A23: 22 | B23: 24 | C23: Tasi | D23: Cozze alla Marinara | E23: TASPEC | F23: TASPEC05 | G23: 0 | L23: =SUMIF(Recipe_Components!$A$2:$A$515,A23,Recipe_Components!$F$2:$F$515) | M23: =IF(AND(K23<>"",L23<>""),L23-K23,"") | N23: =IF(AND(G23<>"",H23<>""),G23-H23,"") | O23: =IF(G23>0,1-L23/G23,"") | Q23: FALSE | R23: FALSE
A24: 23 | B24: 25 | C24: Tasi | D24: Rigatoni alla Arrabbiata | E24: TASPEC | F24: TASPEC06 | G24: 0 | L24: =SUMIF(Recipe_Components!$A$2:$A$515,A24,Recipe_Components!$F$2:$F$515) | M24: =IF(AND(K24<>"",L24<>""),L24-K24,"") | N24: =IF(AND(G24<>"",H24<>""),G24-H24,"") | O24: =IF(G24>0,1-L24/G24,"") | Q24: FALSE | R24: FALSE
A25: 24 | B25: 26 | C25: Tasi | D25: Chorizo Pizza | E25: TASPEC | F25: TASPEC07 | G25: 0 | L25: =SUMIF(Recipe_Components!$A$2:$A$515,A25,Recipe_Components!$F$2:$F$515) | M25: =IF(AND(K25<>"",L25<>""),L25-K25,"") | N25: =IF(AND(G25<>"",H25<>""),G25-H25,"") | O25: =IF(G25>0,1-L25/G25,"") | Q25: FALSE | R25: FALSE
A26: 25 | B26: 27 | C26: Tasi | D26: Nduja, Rocket & Parmesan Pizza | E26: TASPEC | F26: TASPEC08 | G26: 0 | H26: 2.2 | I26: 1.4860768 | J26: 1.8427352 | K26: 0.44582304 | L26: =SUMIF(Recipe_Components!$A$2:$A$515,A26,Recipe_Components!$F$2:$F$515) | M26: =IF(AND(K26<>"",L26<>""),L26-K26,"") | N26: =IF(AND(G26<>"",H26<>""),G26-H26,"") | O26: =IF(G26>0,1-L26/G26,"") | Q26: FALSE | R26: FALSE
A27: 26 | B27: 28 | C27: Tasi | D27: Carpicciosa Pizza | E27: TASPEC | F27: TASPEC09 | G27: 0 | L27: =SUMIF(Recipe_Components!$A$2:$A$515,A27,Recipe_Components!$F$2:$F$515) | M27: =IF(AND(K27<>"",L27<>""),L27-K27,"") | N27: =IF(AND(G27<>"",H27<>""),G27-H27,"") | O27: =IF(G27>0,1-L27/G27,"") | Q27: FALSE | R27: FALSE
A28: 27 | B28: 29 | C28: Tasi | D28: Anchovie & Salsa Verde Pizza | E28: TASPEC | F28: TASPEC10 | G28: 0 | L28: =SUMIF(Recipe_Components!$A$2:$A$515,A28,Recipe_Components!$F$2:$F$515) | M28: =IF(AND(K28<>"",L28<>""),L28-K28,"") | N28: =IF(AND(G28<>"",H28<>""),G28-H28,"") | O28: =IF(G28>0,1-L28/G28,"") | Q28: FALSE | R28: FALSE
A29: 28 | B29: 30 | C29: Tasi | D29: Mediteranian Veg Pizza | E29: TASPEC | F29: TASPEC11 | G29: 0 | L29: =SUMIF(Recipe_Components!$A$2:$A$515,A29,Recipe_Components!$F$2:$F$515) | M29: =IF(AND(K29<>"",L29<>""),L29-K29,"") | N29: =IF(AND(G29<>"",H29<>""),G29-H29,"") | O29: =IF(G29>0,1-L29/G29,"") | Q29: FALSE | R29: FALSE
A30: 29 | B30: 34 | C30: Tasi | D30: Caesar salad | E30: TASALAD | F30: TASALAD01 | G30: 20 | H30: 8.8 | I30: 5.7121333 | J30: 7.0830453 | K30: 1.71364 | L30: =SUMIF(Recipe_Components!$A$2:$A$515,A30,Recipe_Components!$F$2:$F$515) | M30: =IF(AND(K30<>"",L30<>""),L30-K30,"") | N30: =IF(AND(G30<>"",H30<>""),G30-H30,"") | O30: =IF(G30>0,1-L30/G30,"") | Q30: FALSE | R30: FALSE | S30: 11.2 | T30: 0.89375432
A31: 30 | B31: 35 | C31: Tasi | D31: Greek Salad | E31: TASALAD | F31: TASALAD02 | G31: 14 | H31: 7.7 | I31: 5.149 | J31: 6.38476 | K31: 1.5447 | L31: =SUMIF(Recipe_Components!$A$2:$A$515,A31,Recipe_Components!$F$2:$F$515) | M31: =IF(AND(K31<>"",L31<>""),L31-K31,"") | N31: =IF(AND(G31<>"",H31<>""),G31-H31,"") | O31: =IF(G31>0,1-L31/G31,"") | Q31: FALSE | R31: FALSE | S31: 6.3 | T31: 0.8631837143
A32: 31 | B32: 36 | C32: Tasi | D32: Watermelon & Feta salad | E32: TASALAD | F32: TASALAD03 | H32: 6.6 | I32: 4.3721667 | J32: 5.4214867 | K32: 1.31165 | L32: =SUMIF(Recipe_Components!$A$2:$A$515,A32,Recipe_Components!$F$2:$F$515) | M32: =IF(AND(K32<>"",L32<>""),L32-K32,"") | N32: =IF(AND(G32<>"",H32<>""),G32-H32,"") | O32: =IF(G32>0,1-L32/G32,"") | Q32: FALSE | R32: FALSE | S32: -6.6
A33: 32 | B33: 37 | C33: Tasi | D33: Pulled lamb salad | E33: TASALAD | F33: TASALAD04 | G33: 18 | H33: 14.3 | I33: 10.079154 | J33: 12.498151 | K33: 3.0237463 | L33: =SUMIF(Recipe_Components!$A$2:$A$515,A33,Recipe_Components!$F$2:$F$515) | M33: =IF(AND(K33<>"",L33<>""),L33-K33,"") | N33: =IF(AND(G33<>"",H33<>""),G33-H33,"") | O33: =IF(G33>0,1-L33/G33,"") | Q33: FALSE | R33: FALSE | S33: 3.7 | T33: 0.7916974775
A34: 33 | B34: 39 | C34: Tasi | D34: Margherita pizza | E34: TAPIZZA | F34: TAPIZZA01 | G34: 15 | H34: 18.7 | I34: 13.031807 | J34: 16.159441 | K34: 3.9095422 | L34: =SUMIF(Recipe_Components!$A$2:$A$515,A34,Recipe_Components!$F$2:$F$515) | M34: =IF(AND(K34<>"",L34<>""),L34-K34,"") | N34: =IF(AND(G34<>"",H34<>""),G34-H34,"") | O34: =IF(G34>0,1-L34/G34,"") | Q34: FALSE | R34: FALSE | S34: -3.7 | T34: 0.6768111789
A35: 34 | B35: 40 | C35: Tasi | D35: Mushroom and truffle pizza | E35: TAPIZZA | F35: TAPIZZA02 | G35: 18 | H35: 15.4 | I35: 11.27321 | J35: 13.978781 | K35: 3.381963 | L35: =SUMIF(Recipe_Components!$A$2:$A$515,A35,Recipe_Components!$F$2:$F$515) | M35: =IF(AND(K35<>"",L35<>""),L35-K35,"") | N35: =IF(AND(G35<>"",H35<>""),G35-H35,"") | O35: =IF(G35>0,1-L35/G35,"") | Q35: FALSE | R35: FALSE | S35: 2.6 | T35: 0.7670203239
A36: 35 | B36: 41 | C36: Tasi | D36: Parma ham pizza | E36: TAPIZZA | F36: TAPIZZA03 | G36: 19 | H36: 18.7 | I36: 13.374574 | J36: 16.584472 | K36: 4.0123722 | L36: =SUMIF(Recipe_Components!$A$2:$A$515,A36,Recipe_Components!$F$2:$F$515) | M36: =IF(AND(K36<>"",L36<>""),L36-K36,"") | N36: =IF(AND(G36<>"",H36<>""),G36-H36,"") | O36: =IF(G36>0,1-L36/G36,"") | Q36: FALSE | R36: FALSE | S36: 0.3 | T36: 0.7381399202
A37: 36 | B37: 42 | C37: Tasi | D37: Courgette, ricotta pizza | E37: TAPIZZA | F37: TAPIZZA04 | G37: 15 | H37: 18.7 | I37: 13.66101 | J37: 16.939653 | K37: 4.098303 | L37: =SUMIF(Recipe_Components!$A$2:$A$515,A37,Recipe_Components!$F$2:$F$515) | M37: =IF(AND(K37<>"",L37<>""),L37-K37,"") | N37: =IF(AND(G37<>"",H37<>""),G37-H37,"") | O37: =IF(G37>0,1-L37/G37,"") | Q37: FALSE | R37: FALSE | S37: -3.7 | T37: 0.6612069487
A38: 37 | B38: 43 | C38: Tasi | D38: Salami pizza | E38: TAPIZZA | F38: TAPIZZA05 | G38: 18 | H38: 14.3 | I38: 10.109307 | J38: 12.535541 | K38: 3.0327922 | L38: =SUMIF(Recipe_Components!$A$2:$A$515,A38,Recipe_Components!$F$2:$F$515) | M38: =IF(AND(K38<>"",L38<>""),L38-K38,"") | N38: =IF(AND(G38<>"",H38<>""),G38-H38,"") | O38: =IF(G38>0,1-L38/G38,"") | Q38: FALSE | R38: FALSE | S38: 3.7 | T38: 0.7910743157
A39: 38 | B39: 45 | C39: Tasi | D39: Regular fries | E39: TASIDES | F39: TASIDES01 | G39: 5 | H39: 2.2 | I39: 1.52 | J39: 1.8848 | K39: 0.456 | L39: =SUMIF(Recipe_Components!$A$2:$A$515,A39,Recipe_Components!$F$2:$F$515) | M39: =IF(AND(K39<>"",L39<>""),L39-K39,"") | N39: =IF(AND(G39<>"",H39<>""),G39-H39,"") | O39: =IF(G39>0,1-L39/G39,"") | Q39: FALSE | R39: FALSE | S39: 2.8 | T39: 0.886912
A40: 39 | B40: 46 | C40: Tasi | D40: Parmesan fries | E40: TASIDES | F40: TASIDES02 | H40: 4.4 | I40: 2.9 | J40: 3.596 | K40: 0.87 | L40: =SUMIF(Recipe_Components!$A$2:$A$515,A40,Recipe_Components!$F$2:$F$515) | M40: =IF(AND(K40<>"",L40<>""),L40-K40,"") | N40: =IF(AND(G40<>"",H40<>""),G40-H40,"") | O40: =IF(G40>0,1-L40/G40,"") | Q40: FALSE | R40: FALSE | S40: -4.4
A41: 40 | B41: 47 | C41: Tasi | D41: Basil butter baby potatoes | E41: TASIDES | F41: TASIDES03 | G41: 5 | H41: 1.1 | I41: 0.36666667 | J41: 0.45466667 | K41: 0.11 | L41: =SUMIF(Recipe_Components!$A$2:$A$515,A41,Recipe_Components!$F$2:$F$515) | M41: =IF(AND(K41<>"",L41<>""),L41-K41,"") | N41: =IF(AND(G41<>"",H41<>""),G41-H41,"") | O41: =IF(G41>0,1-L41/G41,"") | Q41: FALSE | R41: FALSE | S41: 3.9 | T41: 0.97272
A42: 41 | B42: 48 | C42: Tasi | D42: Local wilted greens | E42: TASIDES | F42: TASIDES04 | G42: 4 | H42: 4.4 | I42: 3.2 | J42: 3.968 | K42: 0.96 | L42: =SUMIF(Recipe_Components!$A$2:$A$515,A42,Recipe_Components!$F$2:$F$515) | M42: =IF(AND(K42<>"",L42<>""),L42-K42,"") | N42: =IF(AND(G42<>"",H42<>""),G42-H42,"") | O42: =IF(G42>0,1-L42/G42,"") | Q42: FALSE | R42: FALSE | S42: -0.4 | T42: 0.7024
A43: 42 | B43: 49 | C43: Tasi | D43: Leaf salad | E43: TASIDES | F43: TASIDES05 | G43: 4 | H43: 4.4 | I43: 3.16325 | J43: 3.92243 | K43: 0.948975 | L43: =SUMIF(Recipe_Components!$A$2:$A$515,A43,Recipe_Components!$F$2:$F$515) | M43: =IF(AND(K43<>"",L43<>""),L43-K43,"") | N43: =IF(AND(G43<>"",H43<>""),G43-H43,"") | O43: =IF(G43>0,1-L43/G43,"") | Q43: FALSE | R43: FALSE | S43: -0.4 | T43: 0.70581775
...

Sheet Menus
A1: menu_id | B1: menu_name | C1: restaurant | D1: guest_count | E1: target_gp | F1: dishes_selected | G1: per_guest_cost | H1: current_sell_per_guest | I1: target_sell_per_guest | J1: total_food_cost | K1: current_menu_revenue | L1: target_menu_revenue | M1: current_gp | N1: gap_to_target_price
A2: 1 | B2: Tasi Demo Menu | C2: Tasi | D2: 40 | E2: 0.75 | F2: =COUNTIF(Menu_Lines!$A$2:$A$10,A2) | G2: =SUMIF(Menu_Lines!$A$2:$A$10,A2,Menu_Lines!$G$2:$G$10) | H2: =SUMIF(Menu_Lines!$A$2:$A$10,A2,Menu_Lines!$H$2:$H$10) | I2: =IF(1-E2>0,G2/(1-E2),"") | J2: =IF(AND(D2<>"",G2<>""),D2*G2,"") | K2: =IF(AND(D2<>"",H2<>""),D2*H2,"") | L2: =IF(AND(D2<>"",I2<>""),D2*I2,"") | M2: =IF(H2>0,1-G2/H2,"") | N2: =IF(AND(I2<>"",H2<>""),I2-H2,"")
A3: 2 | B3: Terraces Demo Menu | C3: Terraces | D3: 50 | E3: 0.75 | F3: =COUNTIF(Menu_Lines!$A$2:$A$10,A3) | G3: =SUMIF(Menu_Lines!$A$2:$A$10,A3,Menu_Lines!$G$2:$G$10) | H3: =SUMIF(Menu_Lines!$A$2:$A$10,A3,Menu_Lines!$H$2:$H$10) | I3: =IF(1-E3>0,G3/(1-E3),"") | J3: =IF(AND(D3<>"",G3<>""),D3*G3,"") | K3: =IF(AND(D3<>"",H3<>""),D3*H3,"") | L3: =IF(AND(D3<>"",I3<>""),D3*I3,"") | M3: =IF(H3>0,1-G3/H3,"") | N3: =IF(AND(I3<>"",H3<>""),I3-H3,"")
A4: 3 | B4: Mikro Nisi Demo Menu | C4: Mikro Nisi | D4: 60 | E4: 0.75 | F4: =COUNTIF(Menu_Lines!$A$2:$A$10,A4) | G4: =SUMIF(Menu_Lines!$A$2:$A$10,A4,Menu_Lines!$G$2:$G$10) | H4: =SUMIF(Menu_Lines!$A$2:$A$10,A4,Menu_Lines!$H$2:$H$10) | I4: =IF(1-E4>0,G4/(1-E4),"") | J4: =IF(AND(D4<>"",G4<>""),D4*G4,"") | K4: =IF(AND(D4<>"",H4<>""),D4*H4,"") | L4: =IF(AND(D4<>"",I4<>""),D4*I4,"") | M4: =IF(H4>0,1-G4/H4,"") | N4: =IF(AND(I4<>"",H4<>""),I4-H4,"")

Sheet Menu_Lines
A1: menu_id | B1: line_sort | C1: course_label | D1: recipe_id | E1: restaurant | F1: dish_name | G1: line_cost | H1: line_sale_price | I1: category
A2: 1 | B2: 1 | C2: Starter | D2: 30 | E2: Tasi | F2: Greek Salad | G2: 1.5447 | H2: 14 | I2: TASALAD
A3: 1 | B3: 2 | C3: Main | D3: 7 | E3: Tasi | F3: Spinach and sea green linguine | G3: 3.6484 | H3: 16 | I3: TAMAIN
A4: 1 | B4: 3 | C4: Dessert | D4: 62 | E4: Tasi | F4: Lemon Posset | G4: 0.7204375 | H4: 7 | I4: TADESSERT
A5: 2 | B5: 1 | C5: Dip | D5: 68 | E5: Terraces | F5: Muhammara | G5: 1.2085846 | H5: 7 | I5: TERDIP
A6: 2 | B6: 2 | C6: Main | D6: 84 | E6: Terraces | F6: Firecooked Chicken | G6: 1.39 | H6: 18 | I6: TERRMAIN
A7: 2 | B7: 3 | C7: Dessert | D7: 111 | E7: Terraces | F7: Lemon Posset | G7: 0.7204375 | H7: 7 | I7: TERRDESSERT
A8: 3 | B8: 1 | C8: Small Plate | D8: 116 | E8: Mikro Nisi | F8: Bread and Dips | G8: 0.87273079 | H8: 12 | I8: MNSMALL
A9: 3 | B9: 2 | C9: Large Plate | D9: 128 | E9: Mikro Nisi | F9: Octopus | G9: 4.92305 | H9: 18 | I9: MNLARGE
A10: 3 | B10: 3 | C10: Small Plate 2 | D10: 124 | E10: Mikro Nisi | F10: Greek salad with crumbled manouri cheese | G10: 2.4529 | H10: 12 | I10: MNSMALL

Sheet Venue_Summary
A1: restaurant | B1: recipe_count | C1: avg_gp_calc | D1: avg_current_sale_price | E1: avg_component_cost | F1: recipes_missing_price | G1: recipes_negative_variance
A2: Mikro Nisi | B2: =COUNTIF(Recipes!$C$2:$C$139,A2) | C2: =AVERAGEIF(Recipes!$C$2:$C$139,A2,Recipes!$O$2:$O$139) | D2: =AVERAGEIF(Recipes!$C$2:$C$139,A2,Recipes!$G$2:$G$139) | E2: =AVERAGEIF(Recipes!$C$2:$C$139,A2,Recipes!$L$2:$L$139) | F2: =COUNTIFS(Recipes!$C$2:$C$139,A2,Recipes!$G$2:$G$139,"") | G2: =COUNTIFS(Recipes!$C$2:$C$139,A2,Recipes!$N$2:$N$139,"<0")
A3: Tasi | B3: =COUNTIF(Recipes!$C$2:$C$139,A3) | C3: =AVERAGEIF(Recipes!$C$2:$C$139,A3,Recipes!$O$2:$O$139) | D3: =AVERAGEIF(Recipes!$C$2:$C$139,A3,Recipes!$G$2:$G$139) | E3: =AVERAGEIF(Recipes!$C$2:$C$139,A3,Recipes!$L$2:$L$139) | F3: =COUNTIFS(Recipes!$C$2:$C$139,A3,Recipes!$G$2:$G$139,"") | G3: =COUNTIFS(Recipes!$C$2:$C$139,A3,Recipes!$N$2:$N$139,"<0")
A4: Terraces | B4: =COUNTIF(Recipes!$C$2:$C$139,A4) | C4: =AVERAGEIF(Recipes!$C$2:$C$139,A4,Recipes!$O$2:$O$139) | D4: =AVERAGEIF(Recipes!$C$2:$C$139,A4,Recipes!$G$2:$G$139) | E4: =AVERAGEIF(Recipes!$C$2:$C$139,A4,Recipes!$L$2:$L$139) | F4: =COUNTIFS(Recipes!$C$2:$C$139,A4,Recipes!$G$2:$G$139,"") | G4: =COUNTIFS(Recipes!$C$2:$C$139,A4,Recipes!$N$2:$N$139,"<0")
